# 🐛 Watermark Bug Fix: Hardcoded 2025-01-01 Default

## **The Bug**

The system had **multiple hardcoded `2025-01-01 00:00:00` fallback values** that would silently overwrite user-set watermarks during error conditions.

### **🚨 Problematic Code Locations**

#### **1. s3_watermark_manager.py:388 (PRIMARY BUG)**
```python
def get_incremental_start_timestamp(self, table_name: str) -> str:
    # ... validation logic ...
    else:
        # Fallback to default
        default_timestamp = "2025-01-01 00:00:00"  # ❌ HARDCODED FUTURE DATE
        logger.debug(f"Using default start timestamp for {table_name}: {default_timestamp}")
        return default_timestamp
```

#### **2. s3_watermark_manager.py:406 (SECONDARY BUG)**
```python
def get_last_watermark(self, table_name: Optional[str] = None) -> str:
    # ...
    else:
        # Return a reasonable default for global watermark queries
        default_timestamp = "2025-01-01 00:00:00"  # ❌ ANOTHER HARDCODED FUTURE DATE
        return default_timestamp
```

#### **3. backup/base.py:744 (TERTIARY BUG)**
```python
def get_table_watermark_timestamp(self, table_name: str) -> str:
    try:
        return self.watermark_manager.get_incremental_start_timestamp(table_name)
    except Exception as e:
        self.logger.error_occurred(e, f"watermark_retrieval_{table_name}")
        # Fallback to default
        return "2025-01-01 00:00:00"  # ❌ YET ANOTHER HARDCODED FUTURE DATE
```

## **How This Bug Was Triggered**

### **User's Scenario**
1. **August 11**: User manually set watermark to `2024-01-01`
2. **August 12**: SSH connection failures occurred (`paramiko.DSSKey` error)
3. **Backup process failed**: All chunks failed due to SSH issues
4. **Error recovery triggered**: System fell back to hardcoded `2025-01-01`
5. **Silent data loss**: User's manual setting was overwritten without warning

### **Common Trigger Scenarios**

#### **Scenario 1: Network/Connectivity Issues**
```bash
# S3 network timeout, VPN disconnection, etc.
python -m src.cli.main sync -t settlement.table_name
# → Falls back to 2025-01-01 silently
```

#### **Scenario 2: File Corruption**
```bash
# Watermark file becomes corrupted
aws s3 cp s3://bucket/watermark/tables/table_name.json - | head -c 10 | aws s3 cp - s3://bucket/watermark/tables/table_name.json
python -m src.cli.main watermark get -t settlement.table_name  
# → Returns 2025-01-01
```

#### **Scenario 3: Permission Issues**
```bash
# S3 permissions temporarily revoked
python -m src.cli.main sync -t settlement.table_name
# → Falls back to 2025-01-01
```

#### **Scenario 4: First-time Table**
```bash
# New table with no watermark set
python -m src.cli.main sync -t new.table_name
# → Uses 2025-01-01 instead of asking user
```

## **Why This Is Dangerous**

### **Data Loss Risk**
- **Skips historical data**: `2025-01-01` start date means data before 2025 is ignored
- **Silent failures**: No warning when fallback is used
- **Overwrites user settings**: Manual watermarks lost during errors

### **Operational Issues**
- **Debugging difficulty**: No clear indication why data is missing
- **Unpredictable behavior**: Same command can behave differently based on network conditions
- **Production reliability**: Critical backups can silently fail

## **The Fix**

### **🔧 New Approach: Fail Fast with Clear Error Messages**

#### **Fixed: s3_watermark_manager.py**
```python
# BEFORE: Silent fallback to 2025-01-01
else:
    default_timestamp = "2025-01-01 00:00:00"
    return default_timestamp

# AFTER: Explicit error with helpful message
else:
    logger.warning(f"No valid watermark found for {table_name}")
    raise ValueError(
        f"No watermark found for table '{table_name}'. "
        f"Please set an initial watermark using: "
        f"python -m src.cli.main watermark set -t {table_name} --timestamp 'YYYY-MM-DD HH:MM:SS'"
    )
```

#### **Fixed: backup/base.py**
```python
# BEFORE: Silent fallback to 2025-01-01
except Exception as e:
    self.logger.error_occurred(e, f"watermark_retrieval_{table_name}")
    return "2025-01-01 00:00:00"

# AFTER: Distinguish between missing watermark vs system error
except ValueError as e:
    # User needs to set initial watermark
    self.logger.error(f"Watermark not found for {table_name}: {e}")
    raise e
except Exception as e:
    self.logger.error_occurred(e, f"watermark_retrieval_{table_name}")
    raise RuntimeError(
        f"Failed to retrieve watermark for '{table_name}' due to system error: {e}. "
        f"Please check S3 connectivity and try again, or reset the watermark if corrupted."
    )
```

### **Benefits of the Fix**

#### **1. No Silent Failures**
```bash
# OLD: Silent fallback
python -m src.cli.main sync -t new.table_name
# Proceeds with 2025-01-01, skips data silently

# NEW: Clear error message
python -m src.cli.main sync -t new.table_name
# ❌ Error: No watermark found for table 'new.table_name'. 
# Please set an initial watermark using: 
# python -m src.cli.main watermark set -t new.table_name --timestamp 'YYYY-MM-DD HH:MM:SS'
```

#### **2. Distinguishes Error Types**
- **Missing watermark**: User action required (set initial watermark)
- **System error**: Infrastructure issue (check S3 connectivity, corruption)

#### **3. Preserves User Intent**
- **No automatic overwrites** of user-set watermarks
- **Explicit user action required** for initial setup
- **Clear guidance** on how to resolve issues

## **Migration Guide**

### **For Existing Tables with Corrupted Watermarks**
```bash
# Check if watermark exists and is valid
python -m src.cli.main watermark get -t settlement.table_name

# If corrupted, reset and set proper starting point
python -m src.cli.main watermark reset -t settlement.table_name
python -m src.cli.main watermark set -t settlement.table_name --timestamp "2024-01-01 00:00:00"
```

### **For New Tables**
```bash
# Must explicitly set initial watermark
python -m src.cli.main watermark set -t new.table_name --timestamp "2024-01-01 00:00:00"

# Then proceed with backup
python -m src.cli.main sync -t new.table_name
```

### **For System Errors**
```bash
# If you get system error (S3 connectivity, etc.)
# 1. Check S3 access
aws s3 ls s3://your-bucket/watermark/tables/

# 2. Test connectivity
python -m src.cli.main watermark get -t settlement.table_name

# 3. If watermark file is corrupted, reset it
python -m src.cli.main watermark reset -t settlement.table_name
python -m src.cli.main watermark set -t settlement.table_name --timestamp "2024-01-01 00:00:00"
```

## **Testing the Fix**

### **Test 1: Missing Watermark**
```bash
# Delete watermark file
aws s3 rm s3://bucket/watermark/tables/test_table.json

# Try to run sync - should get clear error
python -m src.cli.main sync -t test.table
# Expected: ValueError with clear instructions
```

### **Test 2: Network Error**
```bash
# Block S3 access temporarily
# Try to run sync - should get system error (not 2025-01-01 fallback)
python -m src.cli.main sync -t settlement.table_name
# Expected: RuntimeError suggesting connectivity check
```

### **Test 3: Corrupted Watermark**
```bash
# Corrupt watermark file
echo "CORRUPTED" | aws s3 cp - s3://bucket/watermark/tables/table_name.json

# Try to access - should get system error
python -m src.cli.main watermark get -t settlement.table_name
# Expected: RuntimeError suggesting reset if corrupted
```

---

## **🚨 P0 BUG: ID-Only Watermark Retrieval Logic**

**Issue Discovered (September 2, 2025)**: Critical bug in watermark retrieval logic causing ID-only watermarks to be ignored.

### **Technical Root Cause**
The backup system incorrectly treated ID-only watermarks as "no watermark" because it required BOTH watermark existence AND non-null timestamp:

```python
# BUGGY CODE (src/backup/row_based.py:189):
if not watermark or not watermark.last_mysql_data_timestamp:
    # No watermark - start from beginning ❌ WRONG!
    last_id = 0
```

### **Impact**
- **ID-only tables**: Manual ID watermarks completely ignored
- **Data duplication**: System would restart from ID 0 despite manual ID being set
- **User confusion**: Watermark appeared to be set but wasn't used

### **User Scenario**
```bash
# User sets manual ID watermark
python3 -m src.cli.main watermark set -t table_name --id 281623217

# System shows watermark is set correctly
python3 -m src.cli.main watermark get -t table_name
# Shows: "Starting ID (Manual): 281,623,217"

# But sync ignores it and starts from ID 0!
python3 -m src.cli.main sync -t table_name
# Log: "No watermark found, starting from beginning"
# Log: "resume_from_id": 0  ❌ Should be 281623217
```

### **The Fix**
```python
# FIXED CODE:
if not watermark:
    # Truly no watermark
    last_id = 0
elif not watermark.last_mysql_data_timestamp and not getattr(watermark, 'last_processed_id', 0):
    # No timestamp AND no ID - empty watermark
    last_id = 0
else:
    # Valid watermark - use it (timestamp OR ID based)
    last_id = getattr(watermark, 'last_processed_id', 0)
```

### **Verification**
After the fix:
```
Line 57: "last_processed_id": 281623217, "backup_strategy": "manual_cli"  ✅
Line 59: "Resuming row-based backup from watermark", "last_id": 281623217  ✅
Line 67: "WHERE id > 281623217", "safe_last_id": 281623217  ✅
Line 68: "first_row_id": 281623220, "last_row_id": 281651626  ✅
```

### **Prevention**
- **Test ID-only watermarks** separately from timestamp watermarks
- **Validate watermark logic** handles null timestamps correctly
- **Check resume_from_id** matches set manual ID in logs

---

## **Summary**

✅ **Fixed**: No more silent fallbacks to hardcoded future dates  
✅ **Improved**: Clear error messages distinguish missing vs. corrupted watermarks  
✅ **Safer**: User must explicitly set initial watermarks  
✅ **Debuggable**: System errors provide actionable guidance  
✅ **Reliable**: Network issues don't silently corrupt watermark state  
✅ **ID Support**: Manual ID watermarks now work correctly for ID-only tables  

This comprehensive fix prevents multiple data loss scenarios and ensures users maintain control over their watermark settings during both system errors and ID-based CDC strategies.